2020-03-12 17:41:29,669 ERROR: Exception on /auth/reset_password_request [POST] [in c:\users\alexander.danson\documents\github\activity_viewer\venv\lib\site-packages\flask\app.py:1891]
Traceback (most recent call last):
  File "c:\users\alexander.danson\documents\github\activity_viewer\venv\lib\site-packages\flask\app.py", line 2446, in wsgi_app
    response = self.full_dispatch_request()
  File "c:\users\alexander.danson\documents\github\activity_viewer\venv\lib\site-packages\flask\app.py", line 1951, in full_dispatch_request
    rv = self.handle_user_exception(e)
  File "c:\users\alexander.danson\documents\github\activity_viewer\venv\lib\site-packages\flask\app.py", line 1820, in handle_user_exception
    reraise(exc_type, exc_value, tb)
  File "c:\users\alexander.danson\documents\github\activity_viewer\venv\lib\site-packages\flask\_compat.py", line 39, in reraise
    raise value
  File "c:\users\alexander.danson\documents\github\activity_viewer\venv\lib\site-packages\flask\app.py", line 1949, in full_dispatch_request
    rv = self.dispatch_request()
  File "c:\users\alexander.danson\documents\github\activity_viewer\venv\lib\site-packages\flask\app.py", line 1935, in dispatch_request
    return self.view_functions[rule.endpoint](**req.view_args)
  File "C:\Users\alexander.danson\Documents\GitHub\Activity_viewer\app\auth\routes.py", line 60, in reset_password_request
    send_email('Reset your password', sender=Config['ADMINS'][0], recipients=recipients,
TypeError: 'type' object is not subscriptable
2020-03-12 18:04:25,849 INFO: Activity_Viewer startup [in C:\Users\alexander.danson\Documents\GitHub\Activity_viewer\app\__init__.py:64]
2020-03-12 18:04:30,575 ERROR: Exception on /auth/reset_password_request [GET] [in c:\users\alexander.danson\documents\github\activity_viewer\venv\lib\site-packages\flask\app.py:1891]
Traceback (most recent call last):
  File "c:\users\alexander.danson\documents\github\activity_viewer\venv\lib\site-packages\flask\app.py", line 2446, in wsgi_app
    response = self.full_dispatch_request()
  File "c:\users\alexander.danson\documents\github\activity_viewer\venv\lib\site-packages\flask\app.py", line 1951, in full_dispatch_request
    rv = self.handle_user_exception(e)
  File "c:\users\alexander.danson\documents\github\activity_viewer\venv\lib\site-packages\flask\app.py", line 1820, in handle_user_exception
    reraise(exc_type, exc_value, tb)
  File "c:\users\alexander.danson\documents\github\activity_viewer\venv\lib\site-packages\flask\_compat.py", line 39, in reraise
    raise value
  File "c:\users\alexander.danson\documents\github\activity_viewer\venv\lib\site-packages\flask\app.py", line 1949, in full_dispatch_request
    rv = self.dispatch_request()
  File "c:\users\alexander.danson\documents\github\activity_viewer\venv\lib\site-packages\flask\app.py", line 1935, in dispatch_request
    return self.view_functions[rule.endpoint](**req.view_args)
  File "C:\Users\alexander.danson\Documents\GitHub\Activity_viewer\app\auth\routes.py", line 50, in reset_password_request
    if current_user.is_authenticated():
TypeError: 'bool' object is not callable
2020-03-12 18:05:11,369 INFO: Activity_Viewer startup [in C:\Users\alexander.danson\Documents\GitHub\Activity_viewer\app\__init__.py:64]
2020-03-12 18:05:18,449 ERROR: Exception on /auth/reset_password_request [POST] [in c:\users\alexander.danson\documents\github\activity_viewer\venv\lib\site-packages\flask\app.py:1891]
Traceback (most recent call last):
  File "c:\users\alexander.danson\documents\github\activity_viewer\venv\lib\site-packages\flask\app.py", line 2446, in wsgi_app
    response = self.full_dispatch_request()
  File "c:\users\alexander.danson\documents\github\activity_viewer\venv\lib\site-packages\flask\app.py", line 1951, in full_dispatch_request
    rv = self.handle_user_exception(e)
  File "c:\users\alexander.danson\documents\github\activity_viewer\venv\lib\site-packages\flask\app.py", line 1820, in handle_user_exception
    reraise(exc_type, exc_value, tb)
  File "c:\users\alexander.danson\documents\github\activity_viewer\venv\lib\site-packages\flask\_compat.py", line 39, in reraise
    raise value
  File "c:\users\alexander.danson\documents\github\activity_viewer\venv\lib\site-packages\flask\app.py", line 1949, in full_dispatch_request
    rv = self.dispatch_request()
  File "c:\users\alexander.danson\documents\github\activity_viewer\venv\lib\site-packages\flask\app.py", line 1935, in dispatch_request
    return self.view_functions[rule.endpoint](**req.view_args)
  File "C:\Users\alexander.danson\Documents\GitHub\Activity_viewer\app\auth\routes.py", line 56, in reset_password_request
    send_password_reset_email(user)
  File "C:\Users\alexander.danson\Documents\GitHub\Activity_viewer\app\auth\email.py", line 18, in send_password_reset_email
    user=user, token=token),
  File "c:\users\alexander.danson\documents\github\activity_viewer\venv\lib\site-packages\flask\templating.py", line 140, in render_template
    ctx.app,
  File "c:\users\alexander.danson\documents\github\activity_viewer\venv\lib\site-packages\flask\templating.py", line 120, in _render
    rv = template.render(context)
  File "c:\users\alexander.danson\documents\github\activity_viewer\venv\lib\site-packages\jinja2\environment.py", line 1090, in render
    self.environment.handle_exception()
  File "c:\users\alexander.danson\documents\github\activity_viewer\venv\lib\site-packages\jinja2\environment.py", line 832, in handle_exception
    reraise(*rewrite_traceback_stack(source=source))
  File "c:\users\alexander.danson\documents\github\activity_viewer\venv\lib\site-packages\jinja2\_compat.py", line 28, in reraise
    raise value.with_traceback(tb)
  File "C:\Users\alexander.danson\Documents\GitHub\Activity_viewer\app\templates\auth\email\reset_password.txt", line 5, in top-level template code
    {{ url_for('auth/reset_password', token=token, _external=True) }}
  File "c:\users\alexander.danson\documents\github\activity_viewer\venv\lib\site-packages\flask\helpers.py", line 370, in url_for
    return appctx.app.handle_url_build_error(error, endpoint, values)
  File "c:\users\alexander.danson\documents\github\activity_viewer\venv\lib\site-packages\flask\app.py", line 2215, in handle_url_build_error
    reraise(exc_type, exc_value, tb)
  File "c:\users\alexander.danson\documents\github\activity_viewer\venv\lib\site-packages\flask\_compat.py", line 39, in reraise
    raise value
  File "c:\users\alexander.danson\documents\github\activity_viewer\venv\lib\site-packages\flask\helpers.py", line 358, in url_for
    endpoint, values, method=method, force_external=external
  File "c:\users\alexander.danson\documents\github\activity_viewer\venv\lib\site-packages\werkzeug\routing.py", line 2020, in build
    raise BuildError(endpoint, values, method, self)
werkzeug.routing.BuildError: Could not build url for endpoint 'auth/reset_password' with values ['token']. Did you mean 'auth.reset_password_request' instead?
2020-03-12 18:07:03,458 INFO: Activity_Viewer startup [in C:\Users\alexander.danson\Documents\GitHub\Activity_viewer\app\__init__.py:64]
