2020-03-15 19:42:10,856 ERROR: Exception on /auth/reset_password_request [POST] [in c:\users\alexander.danson\documents\github\activity_viewer\venv\lib\site-packages\flask\app.py:1891]
Traceback (most recent call last):
  File "c:\users\alexander.danson\documents\github\activity_viewer\venv\lib\site-packages\flask\app.py", line 2446, in wsgi_app
    response = self.full_dispatch_request()
  File "c:\users\alexander.danson\documents\github\activity_viewer\venv\lib\site-packages\flask\app.py", line 1951, in full_dispatch_request
    rv = self.handle_user_exception(e)
  File "c:\users\alexander.danson\documents\github\activity_viewer\venv\lib\site-packages\flask\app.py", line 1820, in handle_user_exception
    reraise(exc_type, exc_value, tb)
  File "c:\users\alexander.danson\documents\github\activity_viewer\venv\lib\site-packages\flask\_compat.py", line 39, in reraise
    raise value
  File "c:\users\alexander.danson\documents\github\activity_viewer\venv\lib\site-packages\flask\app.py", line 1949, in full_dispatch_request
    rv = self.dispatch_request()
  File "c:\users\alexander.danson\documents\github\activity_viewer\venv\lib\site-packages\flask\app.py", line 1935, in dispatch_request
    return self.view_functions[rule.endpoint](**req.view_args)
  File "C:\Users\alexander.danson\Documents\GitHub\Activity_viewer\app\auth\routes.py", line 56, in reset_password_request
    send_password_reset_email(user)
  File "C:\Users\alexander.danson\Documents\GitHub\Activity_viewer\app\auth\email.py", line 20, in send_password_reset_email
    user=user, token=token))
  File "c:\users\alexander.danson\documents\github\activity_viewer\venv\lib\site-packages\flask\templating.py", line 140, in render_template
    ctx.app,
  File "c:\users\alexander.danson\documents\github\activity_viewer\venv\lib\site-packages\flask\templating.py", line 120, in _render
    rv = template.render(context)
  File "c:\users\alexander.danson\documents\github\activity_viewer\venv\lib\site-packages\jinja2\environment.py", line 1090, in render
    self.environment.handle_exception()
  File "c:\users\alexander.danson\documents\github\activity_viewer\venv\lib\site-packages\jinja2\environment.py", line 832, in handle_exception
    reraise(*rewrite_traceback_stack(source=source))
  File "c:\users\alexander.danson\documents\github\activity_viewer\venv\lib\site-packages\jinja2\_compat.py", line 28, in reraise
    raise value.with_traceback(tb)
  File "C:\Users\alexander.danson\Documents\GitHub\Activity_viewer\app\templates\auth\email\reset_password.html", line 10, in top-level template code
    <p>{{ url_for('auth/reset_password', token=token, _external=True) }}</p>
  File "c:\users\alexander.danson\documents\github\activity_viewer\venv\lib\site-packages\flask\helpers.py", line 370, in url_for
    return appctx.app.handle_url_build_error(error, endpoint, values)
  File "c:\users\alexander.danson\documents\github\activity_viewer\venv\lib\site-packages\flask\app.py", line 2215, in handle_url_build_error
    reraise(exc_type, exc_value, tb)
  File "c:\users\alexander.danson\documents\github\activity_viewer\venv\lib\site-packages\flask\_compat.py", line 39, in reraise
    raise value
  File "c:\users\alexander.danson\documents\github\activity_viewer\venv\lib\site-packages\flask\helpers.py", line 358, in url_for
    endpoint, values, method=method, force_external=external
  File "c:\users\alexander.danson\documents\github\activity_viewer\venv\lib\site-packages\werkzeug\routing.py", line 2020, in build
    raise BuildError(endpoint, values, method, self)
werkzeug.routing.BuildError: Could not build url for endpoint 'auth/reset_password' with values ['token']. Did you mean 'auth.reset_password' instead?
2020-03-15 19:43:15,153 INFO: Activity_Viewer startup [in C:\Users\alexander.danson\Documents\GitHub\Activity_viewer\app\__init__.py:64]
2020-03-15 19:48:45,700 INFO: Activity_Viewer startup [in C:\Users\alexander.danson\Documents\GitHub\Activity_viewer\app\__init__.py:64]
2020-03-15 19:51:02,860 INFO: Activity_Viewer startup [in C:\Users\alexander.danson\Documents\GitHub\Activity_viewer\app\__init__.py:64]
2020-03-20 09:19:17,865 INFO: Activity_Viewer startup [in C:\Users\alexander.danson\Documents\GitHub\Activity_viewer\app\__init__.py:64]
2020-03-20 09:21:04,898 INFO: Activity_Viewer startup [in C:\Users\alexander.danson\Documents\GitHub\Activity_viewer\app\__init__.py:64]
